Workbook
Name _Hlk212526893: 'Brent Schrader'!$G$35

Sheet Master Allocation
A1: Quote Number | B1: Customer Name | C1: Quote Amount | D1: Quote Date | E1: Assignee | F1: Follow Up Date | G1: Contact Name | H1: Contact Number | I1: Actual Order $ | J1: Won/Lost | K1: Won by Follow Up | L1: Notes | M1: Previous Follow Up Date
A2: {=IF(_xlfn.VSTACK(_xlfn._xlws.FILTER('Tami Knoell'!A2:M513,'Tami Knoell'!A2:A513<>""),_xlfn._xlws.FILTER('Brent Schrader'!A2:M547,'Brent Schrader'!A2:A547<>""),_xlfn._xlws.FILTER('Eric Simpson'!A2:M529,'Eric Simpson'!A2:A529<>""),_xlfn._xlws.FILTER('LuWanna Morris'!A4:M528,'LuWanna Morris'!A4:A528<>""),_xlfn._xlws.FILTER('Reid Kincaid'!A2:M494,'Reid Kincaid'!A2:A494<>""))="","",_xlfn.VSTACK(_xlfn._xlws.FILTER('Tami Knoell'!A2:M513,'Tami Knoell'!A2:A513<>""),_xlfn._xlws.FILTER('Brent Schrader'!A2:M547,'Brent Schrader'!A2:A547<>""),_xlfn._xlws.FILTER('Eric Simpson'!A2:M529,'Eric Simpson'!A2:A529<>""),_xlfn._xlws.FILTER('LuWanna Morris'!A4:M528,'LuWanna Morris'!A4:A528<>""),_xlfn._xlws.FILTER('Reid Kincaid'!A2:M494,'Reid Kincaid'!A2:A494<>"")))} -> 190629 | B2: ABF Labs/American Blending & Filling/Visual Pak | C2: 2462.2 | D2: 46031 | E2: Tami Knoell | F2: none required | G2: Jesus Diaz | H2: Jesus.Diaz@vpplastics.com | I2: 1846.65 | J2: Won | K2: FALSE | L2: Customer already proceeded to order SO #426550 01/12, Closed quote as Won 02/20/2026
A3: 190875 | B3: AOCUSA – Amalie Oil | C3: 1684.68 | D3: 46038 | E3: Tami Knoell | F3: 46073 | G3: Pedro Mendoza | H3: pedrom@amalie.com | K3: FALSE | L3: Pending
A4: 190806 | B4: MD Packaging | C4: 2106.22 | D4: 46037 | E4: Tami Knoell | F4: none required | G4: Yaroslav Lesho | H4: yaroslav@thetesseragroup.com | K4: FALSE | L4: Quote previously incomplete, Finalized with new quote amount 02/18/2026
A5: 190418 | B5: Motion Industries | C5: 1944.03 | D5: 46030 | E5: Tami Knoell | F5: none required | G5: Stephanie Bogues | H5: Stephanie.Bogues@motion.com | I5: 1944.03 | J5: Won | K5: FALSE | L5: Customer already proceeded to order SO #426378 01/08, Closed quote as Won 02/20/2026
A6: 190844 | B6: PepsiCo | C6: 13162.58 | D6: 46037 | E6: Tami Knoell | F6: none required | G6: Robert Wright | H6: Robert.Wright4@pepsico.com | I6: 13162.58 | J6: Won | K6: FALSE | L6: Customer already proceeded to order SO #428853 02/26, Closed quote as Won 02/27/2026
A7: 190839 | B7: Shorr Packaging Corp | C7: 2922.19 | D7: 46037 | E7: Tami Knoell | F7: 46077 | G7: Gary McPherson | H7: parts@shorr.com | I7: 348 | J7: Won | K7: FALSE | L7: Customer already proceeded to order SO #427080 01/22 for 2 of 4 items quoted, Closed quote as Won 02/25/2026
A8: 190830 | B8: PepsiCo | C8: 4848.05 | D8: 46041 | E8: Alisha Teslow | F8: none required | G8: Robert Wright | H8: Robert.Wright4@pepsico.com | I8: 4848.05 | J8: Won | K8: FALSE | L8: Customer already proceeded to order SO #428854 02/26, Closed quote as Won 02/27/2026
A9: 190826 | B9: United States Gypsum Company | C9: 2184 | D9: 46037 | E9: Alisha Teslow | F9: 46080 | G9: Manuel Piza | H9: mpiza@usg.com | K9: FALSE | L9: Pending
A10: 191759 | B10: Amazon.com | C10: 1882.65 | E10: Tami Knoell | F10: 46077 | G10: Lili Hall | H10: lilihall@amazon.com | K10: FALSE | L10: Quote incomplete, Pending part number verification from customer
A11: 191539 | B11: Cargill | C11: 6368 | D11: 46057 | E11: Tami Knoell | F11: none required | G11: David Campbell | H11: d_campbell@cargill.com | I11: 6368 | J11: Won | K11: FALSE | L11: Customer already proceeded to order SO #427856 02/05, Closed quote as Won 02/24/2026
A12: 191623 | B12: George Delallo Company | C12: 3226.47 | D12: 46059 | E12: Tami Knoell | F12: 46077 | G12: Ron Crofutt | H12: rcrofutt3716@gmail.com | K12: FALSE | L12: Pending
A13: 191639 | B13: JBS USA | C13: 5424 | E13: Tami Knoell | F13: none required | G13: Robert Wilson, Mike Solze | H13: Robert.Wilson5@jbssa.com, Mike.Solze@jbssa.com | K13: FALSE | L13: Quote incomplete, Still pending sourcing information from Procurement Team 02/27/2026
A14: 191910 | B14: PLZ Corp/Follmer Dev/Chicago Aerosol | C14: 5653.73 | E14: Tami Knoell | F14: 46079 | G14: Kaleb Fredericks | H14: Kaleb.Fredericks@plzcorp.com | K14: FALSE | L14: Pending
A15: 191532 | B15: Perdue Farms | C15: 2085.4 | D15: 46057 | E15: Tami Knoell | F15: 46077 | G15: Levary Little | H15: Levary.Little@perdue.com | K15: FALSE | L15: Pending
A16: 191481 | B16: Pete & Gerry's Organics, LLC | C16: 2778 | D16: 46057 | E16: Tami Knoell | F16: none required | G16: Daniel Yawn | H16: dyawn@peteandgerrys.com | I16: 2778 | J16: Won | K16: FALSE | L16: Customer already proceeded to order SO #427754 02/04/2026
A17: 191864 | B17: Sugar Foods Corporation | C17: 2370 | D17: 46065 | E17: Tami Knoell | F17: 46080 | G17: Michael Eskew | H17: meskew@sugarfoods.com | K17: FALSE | L17: Pending
A18: 190412 | B18: Tyson Foods, Inc. HQ | C18: 9177 | D18: 46024 | E18: Brent Schrader | F18: 46069 | G18: Edward Krezek | H18: Edward Krezek | I18: 9177 | J18: won | K18: TRUE | L18: sent email 427571 | M18: 46051
A19: 190460 | B19: ZXP Technologies | C19: 16000 | D19: 46028 | E19: Brent Schrader | F19: 46069 | G19: Bobby Lawder | K19: FALSE | L19: sent email 2nd email sent | M19: 46051
A20: 190526 | B20: ConAgra / Lamb Weston | C20: 4143.2 | D20: 46029 | E20: Brent Schrader | F20: 46069 | G20: Matthew Hites | K20: FALSE | L20: sent email, 2nd email, should be ordering soon | M20: 46051
A21: 190525 | B21: Hormel Foods | C21: 5572.88 | D21: 46029 | E21: Brent Schrader | F21: 46069 | G21: Blake_Robert_W' | I21: 1394 | J21: won | K21: FALSE | L21: sent email , ordered 1 door | M21: 46051
A22: 190413 | B22: Tyson Foods, Inc. HQ | C22: 9800.68 | D22: 46029 | E22: Brent Schrader | F22: 46069 | G22: Edward Krezek | H22: Edward Krezek | I22: 9721 | J22: won | K22: TRUE | L22: sent email 427568 | M22: 46051
A23: 190612 | B23: MD Packaging | C23: 3839.2 | D23: 46031 | E23: Brent Schrader | F23: 46069 | K23: FALSE | L23: customer has not ordered yet | M23: 46051
A24: 190594 | B24: Mitek Industries, Inc. | C24: 8641.46 | D24: 46031 | E24: Brent Schrader | F24: 46069 | G24: Mel.Butler@mii.com | K24: FALSE | L24: 2nd email | M24: 46051
A25: 190677 | B25: Bob Evans | C25: 2115 | D25: 46034 | E25: Brent Schrader | F25: 46069 | G25: jody.cukovecki@bobevansfoods.com | K25: FALSE | L25: sent email 2nd email sent | M25: 46051
A26: 190680 | B26: ConAgra / Lamb Weston | C26: 5400 | D26: 46034 | E26: Brent Schrader | F26: 46069 | G26: Bryan.Sumner@lambweston.com | K26: FALSE | L26: sent email 2nd email sent | M26: 46052
A27: 190709 | B27: Bob Evans | C27: 2698 | D27: 46035 | E27: Brent Schrader | F27: 46069 | G27: james.richardson@bobevansfarms.com | K27: FALSE | L27: sent email 2nd email sent | M27: 46052
A28: 190701 | B28: Ecolab | C28: 12743.37 | D28: 46035 | E28: Brent Schrader | F28: 46069 | G28: matthew.glover@ecolab.com | K28: FALSE | L28: sent email, may order some, killed rsp quote | M28: 46052
A29: 190549 | B29: RWS One | C29: 44413.08 | D29: 46035 | E29: Brent Schrader | F29: 46069 | G29: ryand@umpquadairy.com | K29: FALSE | L29: sent email, checking parts against stock, may order some, closed quote, sent follow up email | M29: 46052
A30: 190759 | B30: Bimbo Bakeries | C30: 2592.55 | D30: 46036 | E30: Brent Schrader | F30: 46069 | G30: Jeffrey.Eaker@grupobimbo.com | I30: 2593 | J30: won | K30: TRUE | L30: sent email, 427515 | M30: 46052
A31: 191448 | B31: Amcor Rigid Plastics | C31: 2988 | D31: 46055 | E31: Brent Schrader | F31: 46070 | I31: 2988 | J31: won | K31: FALSE | L31: 427650
A32: 191461 | B32: National Beef / Iowa Premium | C32: 1529.88 | D32: 46055 | E32: Brent Schrader | F32: 46070 | I32: 1530 | J32: won | K32: FALSE | L32: 427623
A33: 191458 | B33: Niagara Bottling LLC | C33: 14262 | D33: 46055 | E33: Brent Schrader | F33: 46070 | G33: briabrown@niagarawater.com | K33: FALSE | L33: sent email
A34: 191449 | B34: PLZ Corp/Follmer Dev/Chicago Aerosol | C34: 2014 | D34: 46055 | E34: Brent Schrader | F34: 46070 | I34: 2014 | J34: won | K34: FALSE | L34: 427646
A35: 191464 | B35: Ventura Foods | C35: 1976.83 | D35: 46055 | E35: Brent Schrader | F35: 46070 | I35: 1977 | J35: won | K35: FALSE | L35: 427637
A36: 191448 | B36: Amcor Rigid Plastics | C36: 2988 | D36: 46055 | E36: Brent Schrader | F36: 46079 | I36: 2988 | J36: won | K36: FALSE | L36: 427650
A37: 191461 | B37: National Beef / Iowa Premium | C37: 1529.88 | D37: 46055 | E37: Brent Schrader | F37: 46079 | I37: 1630 | J37: won | K37: FALSE | L37: 427623
A38: 191458 | B38: Niagara Bottling LLC | C38: 14262 | D38: 46055 | E38: Brent Schrader | F38: 46079 | G38: briabrown@niagarawater.com | K38: FALSE | L38: sent email 2nd email sent
A39: 191449 | B39: PLZ Corp/Follmer Dev/Chicago Aerosol | C39: 2014 | D39: 46055 | E39: Brent Schrader | F39: 46079 | I39: 2014 | J39: won | K39: FALSE | L39: 427646
A40: 191464 | B40: Ventura Foods | C40: 1976.83 | D40: 46055 | E40: Brent Schrader | F40: 46079 | I40: 1977 | J40: won | K40: FALSE | L40: 427637
...

Sheet Tami Knoell
A1: Quote Number | B1: Cust. Name | C1: Quote Amount | D1: Quote Entry Date | E1: Assignee | F1: Follow Up Date | G1: Contact Name | H1: Contact Number | I1: Actual Order $ | J1: Won/Lost | K1: Won by Follow Up? | L1: Notes | M1: Previous Follow Up Date
A2: 190629 | B2: ABF Labs/American Blending & Filling/Visual Pak | C2: 2462.2 | D2: 46031 | E2: Tami Knoell | F2: none required | G2: Jesus Diaz | H2: Jesus.Diaz@vpplastics.com | I2: 1846.65 | J2: Won | K2: FALSE | L2: Customer already proceeded to order SO #426550 01/12, Closed quote as Won 02/20/2026
A3: 190875 | B3: AOCUSA – Amalie Oil | C3: 1684.68 | D3: 46038 | E3: Tami Knoell | F3: 46073 | G3: Pedro Mendoza | H3: pedrom@amalie.com | K3: FALSE | L3: Pending
A4: 190806 | B4: MD Packaging | C4: 2106.22 | D4: 46037 | E4: Tami Knoell | F4: none required | G4: Yaroslav Lesho | H4: yaroslav@thetesseragroup.com | K4: FALSE | L4: Quote previously incomplete, Finalized with new quote amount 02/18/2026
A5: 190418 | B5: Motion Industries | C5: 1944.03 | D5: 46030 | E5: Tami Knoell | F5: none required | G5: Stephanie Bogues | H5: Stephanie.Bogues@motion.com | I5: 1944.03 | J5: Won | K5: FALSE | L5: Customer already proceeded to order SO #426378 01/08, Closed quote as Won 02/20/2026
A6: 190844 | B6: PepsiCo | C6: 13162.58 | D6: 46037 | E6: Tami Knoell | F6: none required | G6: Robert Wright | H6: Robert.Wright4@pepsico.com | I6: 13162.58 | J6: Won | K6: FALSE | L6: Customer already proceeded to order SO #428853 02/26, Closed quote as Won 02/27/2026
A7: 190839 | B7: Shorr Packaging Corp | C7: 2922.19 | D7: 46037 | E7: Tami Knoell | F7: 46077 | G7: Gary McPherson | H7: parts@shorr.com | I7: 348 | J7: Won | K7: FALSE | L7: Customer already proceeded to order SO #427080 01/22 for 2 of 4 items quoted, Closed quote as Won 02/25/2026
A8: 190830 | B8: PepsiCo | C8: 4848.05 | D8: 46041 | E8: Alisha Teslow | F8: none required | G8: Robert Wright | H8: Robert.Wright4@pepsico.com | I8: 4848.05 | J8: Won | K8: FALSE | L8: Customer already proceeded to order SO #428854 02/26, Closed quote as Won 02/27/2026
A9: 190826 | B9: United States Gypsum Company | C9: 2184 | D9: 46037 | E9: Alisha Teslow | F9: 46080 | G9: Manuel Piza | H9: mpiza@usg.com | K9: FALSE | L9: Pending
A10: 191759 | B10: Amazon.com | C10: 1882.65 | E10: Tami Knoell | F10: 46077 | G10: Lili Hall | H10: lilihall@amazon.com | K10: FALSE | L10: Quote incomplete, Pending part number verification from customer
A11: 191539 | B11: Cargill | C11: 6368 | D11: 46057 | E11: Tami Knoell | F11: none required | G11: David Campbell | H11: d_campbell@cargill.com | I11: 6368 | J11: Won | K11: FALSE | L11: Customer already proceeded to order SO #427856 02/05, Closed quote as Won 02/24/2026
A12: 191623 | B12: George Delallo Company | C12: 3226.47 | D12: 46059 | E12: Tami Knoell | F12: 46077 | G12: Ron Crofutt | H12: rcrofutt3716@gmail.com | K12: FALSE | L12: Pending
A13: 191639 | B13: JBS USA | C13: 5424 | E13: Tami Knoell | F13: none required | G13: Robert Wilson, Mike Solze | H13: Robert.Wilson5@jbssa.com, Mike.Solze@jbssa.com | K13: FALSE | L13: Quote incomplete, Still pending sourcing information from Procurement Team 02/27/2026
A14: 191910 | B14: PLZ Corp/Follmer Dev/Chicago Aerosol | C14: 5653.73 | E14: Tami Knoell | F14: 46079 | G14: Kaleb Fredericks | H14: Kaleb.Fredericks@plzcorp.com | K14: FALSE | L14: Pending
A15: 191532 | B15: Perdue Farms | C15: 2085.4 | D15: 46057 | E15: Tami Knoell | F15: 46077 | G15: Levary Little | H15: Levary.Little@perdue.com | K15: FALSE | L15: Pending
A16: 191481 | B16: Pete & Gerry's Organics, LLC | C16: 2778 | D16: 46057 | E16: Tami Knoell | F16: none required | G16: Daniel Yawn | H16: dyawn@peteandgerrys.com | I16: 2778 | J16: Won | K16: FALSE | L16: Customer already proceeded to order SO #427754 02/04/2026
A17: 191864 | B17: Sugar Foods Corporation | C17: 2370 | D17: 46065 | E17: Tami Knoell | F17: 46080 | G17: Michael Eskew | H17: meskew@sugarfoods.com | K17: FALSE | L17: Pending
K18: FALSE
B21: Total | C21: =SUM(Tami[Quote Amount]) -> 61102.2

Sheet Brent Schrader
A1: Quote Number | B1: Cust. Name | C1: Quote Amount | D1: Quote Entry Date | E1: Assignee | F1: Follow Up Date | G1: Contact Name | H1: Contact Number | I1: Actual Order $ | J1: Won/Lost | K1: Won by Follow Up? | L1: Notes | M1: Previous Follow Up Date
A2: 190412 | B2: Tyson Foods, Inc. HQ | C2: 9177 | D2: 46024 | E2: Brent Schrader | F2: 46069 | G2: Edward Krezek | H2: Edward Krezek | I2: 9177 | J2: won | K2: TRUE | L2: sent email 427571 | M2: 46051
A3: 190460 | B3: ZXP Technologies | C3: 16000 | D3: 46028 | E3: Brent Schrader | F3: 46069 | G3: Bobby Lawder | K3: FALSE | L3: sent email 2nd email sent | M3: 46051
A4: 190526 | B4: ConAgra / Lamb Weston | C4: 4143.2 | D4: 46029 | E4: Brent Schrader | F4: 46069 | G4: Matthew Hites | K4: FALSE | L4: sent email, 2nd email, should be ordering soon | M4: 46051
A5: 190525 | B5: Hormel Foods | C5: 5572.88 | D5: 46029 | E5: Brent Schrader | F5: 46069 | G5: Blake_Robert_W' | I5: 1394 | J5: won | K5: FALSE | L5: sent email , ordered 1 door | M5: 46051
A6: 190413 | B6: Tyson Foods, Inc. HQ | C6: 9800.68 | D6: 46029 | E6: Brent Schrader | F6: 46069 | G6: Edward Krezek | H6: Edward Krezek | I6: 9721 | J6: won | K6: TRUE | L6: sent email 427568 | M6: 46051
A7: 190612 | B7: MD Packaging | C7: 3839.2 | D7: 46031 | E7: Brent Schrader | F7: 46069 | K7: FALSE | L7: customer has not ordered yet | M7: 46051
A8: 190594 | B8: Mitek Industries, Inc. | C8: 8641.46 | D8: 46031 | E8: Brent Schrader | F8: 46069 | G8: Mel.Butler@mii.com | K8: FALSE | L8: 2nd email | M8: 46051
A9: 190677 | B9: Bob Evans | C9: 2115 | D9: 46034 | E9: Brent Schrader | F9: 46069 | G9: jody.cukovecki@bobevansfoods.com | K9: FALSE | L9: sent email 2nd email sent | M9: 46051
A10: 190680 | B10: ConAgra / Lamb Weston | C10: 5400 | D10: 46034 | E10: Brent Schrader | F10: 46069 | G10: Bryan.Sumner@lambweston.com | K10: FALSE | L10: sent email 2nd email sent | M10: 46052
A11: 190709 | B11: Bob Evans | C11: 2698 | D11: 46035 | E11: Brent Schrader | F11: 46069 | G11: james.richardson@bobevansfarms.com | K11: FALSE | L11: sent email 2nd email sent | M11: 46052
A12: 190701 | B12: Ecolab | C12: 12743.37 | D12: 46035 | E12: Brent Schrader | F12: 46069 | G12: matthew.glover@ecolab.com | K12: FALSE | L12: sent email, may order some, killed rsp quote | M12: 46052
A13: 190549 | B13: RWS One | C13: 44413.08 | D13: 46035 | E13: Brent Schrader | F13: 46069 | G13: ryand@umpquadairy.com | K13: FALSE | L13: sent email, checking parts against stock, may order some, closed quote, sent follow up email | M13: 46052
A14: 190759 | B14: Bimbo Bakeries | C14: 2592.55 | D14: 46036 | E14: Brent Schrader | F14: 46069 | G14: Jeffrey.Eaker@grupobimbo.com | I14: 2593 | J14: won | K14: TRUE | L14: sent email, 427515 | M14: 46052
A15: 191448 | B15: Amcor Rigid Plastics | C15: 2988 | D15: 46055 | E15: Brent Schrader | F15: 46070 | I15: 2988 | J15: won | K15: FALSE | L15: 427650
A16: 191461 | B16: National Beef / Iowa Premium | C16: 1529.88 | D16: 46055 | E16: Brent Schrader | F16: 46070 | I16: 1530 | J16: won | K16: FALSE | L16: 427623
A17: 191458 | B17: Niagara Bottling LLC | C17: 14262 | D17: 46055 | E17: Brent Schrader | F17: 46070 | G17: briabrown@niagarawater.com | K17: FALSE | L17: sent email
A18: 191449 | B18: PLZ Corp/Follmer Dev/Chicago Aerosol | C18: 2014 | D18: 46055 | E18: Brent Schrader | F18: 46070 | I18: 2014 | J18: won | K18: FALSE | L18: 427646
A19: 191464 | B19: Ventura Foods | C19: 1976.83 | D19: 46055 | E19: Brent Schrader | F19: 46070 | I19: 1977 | J19: won | K19: FALSE | L19: 427637
A20: 191448 | B20: Amcor Rigid Plastics | C20: 2988 | D20: 46055 | E20: Brent Schrader | F20: 46079 | I20: 2988 | J20: won | K20: FALSE | L20: 427650
A21: 191461 | B21: National Beef / Iowa Premium | C21: 1529.88 | D21: 46055 | E21: Brent Schrader | F21: 46079 | I21: 1630 | J21: won | K21: FALSE | L21: 427623
A22: 191458 | B22: Niagara Bottling LLC | C22: 14262 | D22: 46055 | E22: Brent Schrader | F22: 46079 | G22: briabrown@niagarawater.com | K22: FALSE | L22: sent email 2nd email sent
A23: 191449 | B23: PLZ Corp/Follmer Dev/Chicago Aerosol | C23: 2014 | D23: 46055 | E23: Brent Schrader | F23: 46079 | I23: 2014 | J23: won | K23: FALSE | L23: 427646
A24: 191464 | B24: Ventura Foods | C24: 1976.83 | D24: 46055 | E24: Brent Schrader | F24: 46079 | I24: 1977 | J24: won | K24: FALSE | L24: 427637
A25: 191480 | B25: JBS USA | C25: 1639 | D25: 46056 | E25: Brent Schrader | F25: 46070 | G25: Diedra.Henderson@pilgrims.com' | K25: FALSE | L25: sent email
A26: 191490 | B26: Tyson Foods, Inc. HQ | C26: 2093 | D26: 46056 | E26: Brent Schrader | F26: 46070 | I26: 2093 | J26: won | K26: FALSE | L26: 427844
A27: 191480 | B27: JBS USA | C27: 1639 | D27: 46056 | E27: Brent Schrader | F27: 46079 | K27: FALSE | L27: Lost cust does not need
A28: 191490 | B28: Tyson Foods, Inc. HQ | C28: 2093 | D28: 46056 | E28: Brent Schrader | F28: 46079 | I28: 2093 | J28: won | K28: FALSE | L28: 427844
A29: 191530 | B29: Tyson Foods, Inc. HQ | C29: 4901 | D29: 46057 | E29: Brent Schrader | F29: 46070 | I29: 4901 | J29: won | K29: FALSE | L29: 428163
A30: 191530 | B30: Tyson Foods, Inc. HQ | C30: 4901 | D30: 46057 | E30: Brent Schrader | F30: 46079 | I30: 4901 | J30: won | K30: FALSE | L30: 428163
A31: 191524 | B31: B Braun Medical | C31: 42812 | D31: 46058 | E31: Brent Schrader | F31: 46070 | G31: steven.daly@bbraunusa.com | K31: FALSE | L31: sent email
A32: 191561 | B32: George Delallo Company | C32: 2286 | D32: 46058 | E32: Brent Schrader | F32: 46070 | G32: ronald.crofutt@delallo.com | K32: FALSE | L32: sent email
A33: 191514 | B33: Harmoni Inc dba Uncle Matt's Organic | C33: 28825.23 | D33: 46058 | E33: Brent Schrader | F33: 46070 | G33: Damien@unclematts.com | K33: FALSE | L33: sent email
A34: 191584 | B34: Harmoni Inc dba Uncle Matt's Organic | C34: 2211.56 | D34: 46058 | E34: Brent Schrader | F34: 46070 | I34: 2212 | J34: won | K34: FALSE | L34: 427864
A35: 191590 | B35: Silgan Holdings | C35: 1820 | D35: 46058 | E35: Brent Schrader | F35: 46070 | I35: 647 | J35: won | K35: FALSE | L35: 427891
A36: 191573 | B36: Tyson Foods, Inc. HQ | C36: 2716 | D36: 46058 | E36: Brent Schrader | F36: 46070 | I36: 2716 | J36: won | K36: FALSE | L36: 427818
A37: 191524 | B37: B Braun Medical | C37: 42812 | D37: 46058 | E37: Brent Schrader | F37: 46079 | K37: FALSE | L37: Lost cust does not need
A38: 191561 | B38: George Delallo Company | C38: 2286 | D38: 46058 | E38: Brent Schrader | F38: 46079 | I38: 2491 | J38: won | K38: FALSE | L38: 428688
A39: 191514 | B39: Harmoni Inc dba Uncle Matt's Organic | C39: 28825.23 | D39: 46058 | E39: Brent Schrader | F39: 46079 | K39: FALSE | L39: sent email 2nd email sent
A40: 191584 | B40: Harmoni Inc dba Uncle Matt's Organic | C40: 2211.56 | D40: 46058 | E40: Brent Schrader | F40: 46079 | I40: 2212 | J40: won | K40: TRUE | L40: 427864
...

Sheet Eric Simpson
A1: Quote Number | B1: Cust. Name | C1: Quote Amount | D1: Quote Entry Date | E1: Assignee | F1: Follow Up Date | G1: Contact Name | H1: Contact Number | I1: Actual Order $ | J1: Won/Lost | K1: Won by Follow Up? | L1: Notes | M1: Previous Follow Up Date
A2: 191722 | B2: ADAMA dba Makhteshim Agan of North America | C2: 5957.55 | D2: 46063 | E2: Eric Simpson | F2: 46069 | G2: Christopher Pearson <christopher.pearson@adama.com> | I2: 5957.55 | J2: Won | K2: FALSE | L2: Already Ordered From the Webstore
A3: 191747 | B3: Alpla | C3: 2976.89 | D3: 46065 | E3: Eric Simpson | F3: 46069 | I3: 2976.89 | J3: Won | K3: FALSE | L3: Ordered on SO# 428153
A4: 191892 | B4: Alpla | C4: 2675.38 | D4: 46066 | E4: Eric Simpson | F4: 46069 | G4: David.Mccollum@alpla.com | K4: FALSE | L4: Sent Second Request
A5: 191457 | B5: Amcor Rigid Plastics | C5: 5422.38 | D5: 46055 | E5: Eric Simpson | F5: 46069 | G5: Claycraig@berryglobal.com | H5: 731-935-1395 | I5: 5422.38 | J5: Won | K5: FALSE | L5: Ordered on SO# 427649
A6: 191877 | B6: Aspire Bakeries | C6: 1788 | D6: 46066 | E6: Eric Simpson | F6: 46070 | G6: Gary Marchetti | I6: 1788 | J6: Won | K6: FALSE | L6: Ordered on SO# 428222
A7: 191880 | B7: Burlington Coat Factory | C7: 3862.94 | D7: 46066 | E7: Eric Simpson | F7: 46070 | G7: Jasminne Sanchez | K7: FALSE | L7: Sent Second Request
A8: 191881 | B8: Burlington Coat Factory | C8: 2365.5 | D8: 46066 | E8: Eric Simpson | F8: 46070 | G8: Jasminne Sanchez | K8: FALSE | L8: Sent Second Request
A9: 191459 | B9: Church & Dwight | C9: 6508.2 | D9: 46055 | E9: Eric Simpson | F9: 46070 | G9: Justin Lang | I9: 6508.2 | J9: Won | K9: FALSE | L9: Ordered on SO# 427619
A10: 191828 | B10: Country Pure Foods/Silver Springs Citrus | C10: 2667.14 | D10: 46066 | E10: Eric Simpson | F10: 46070 | G10: Kyle Valentin | I10: 2667.14 | J10: Won | K10: FALSE | L10: Ordered on SO# 428234
A11: 191751 | B11: Furmano Foods | C11: 4299.68 | D11: 46065 | E11: Eric Simpson | F11: 46076 | G11: Scott Fox | I11: 4299.68 | J11: Won | K11: FALSE | L11: Ordered on SO# 428154
A12: 191817 | B12: Gallo Glass / E&J Gallo Winery / G3 Enterprises | C12: 17508.44 | D12: 46064 | E12: Eric Simpson | F12: 46076 | G12: MARTY SHEEK | J12: Lost | K12: FALSE | L12: Quote closed
A13: 191785 | B13: Henkel | C13: 1512 | D13: 46065 | E13: Eric Simpson | F13: 46076 | G13: Jeffery Keeley | I13: 1512 | J13: Won | K13: FALSE | L13: Ordered on SO# 428178
A14: 191840 | B14: Ken's Foods, LLC | C14: 4912.84 | D14: 46065 | E14: Eric Simpson | F14: 46076 | I14: 4912.84 | J14: Won | K14: FALSE | L14: Ordered on SO# 428179
A15: 191789 | B15: Ocean Spray Cranberries | C15: 2256 | D15: 46066 | E15: Eric Simpson | F15: 46076 | G15: Jeff Bortz | I15: 2256 | J15: Won | K15: FALSE | L15: Ordered on SO# 428274
A16: 191733 | B16: Ryder Integrated Logistics / former Tech Packaging | C16: 1847 | E16: Eric Simpson | F16: 46076 | J16: Lost | K16: FALSE | L16: Closed Quote
A17: 191777 | B17: S.C. Johnson & Son | C17: 4553.38 | D17: 46065 | E17: Eric Simpson | F17: 46076 | G17: Renee Frederick | I17: 4553.38 | J17: Won | K17: FALSE | L17: Ordered on SO# 428208
A18: 191774 | B18: S.C. Johnson & Son | C18: 1826.25 | D18: 46065 | E18: Eric Simpson | F18: 46076 | G18: 428213 | I18: 1826.25 | J18: Won | K18: FALSE | L18: Ordered on SO# 428213
A19: 191772 | B19: Silgan Holdings | C19: 1811 | D19: 46064 | E19: Eric Simpson | F19: 46076 | G19: Justina Robbins | K19: FALSE | L19: Sent Second Request
A20: 191779 | B20: Spears Manufacturing Company | C20: 4470 | D20: 46064 | E20: Eric Simpson | F20: 46076 | G20: Ernie Garcia | I20: 1282.25 | J20: Won | K20: FALSE | L20: Ordered on SO# 306674
A21: 191769 | B21: Sustainable Beef LLC | C21: 5233.34 | D21: 46064 | E21: Eric Simpson | F21: 46076 | G21: Billy Fisk | I21: 5233.34 | J21: Won | K21: FALSE | L21: Ordered on SO# 428419
A22: 191882 | B22: Tyson Foods, Inc. HQ | C22: 7470 | D22: 46066 | E22: Eric Simpson | F22: 46076 | G22: Jacob Brainard | I22: 7470 | J22: Won | K22: FALSE | L22: Ordered on multiple POs
A23: 191836 | B23: United States Gypsum Company | C23: 5610.88 | D23: 46065 | E23: Eric Simpson | F23: 46076 | G23: K Chafee | K23: FALSE | L23: Sent Second Request
A24: 191722 | B24: ADAMA dba Makhteshim Agan of North America | C24: 5957.55 | D24: 46063 | E24: Eric Simpson | F24: 46078 | I24: 5957.55 | J24: Won | K24: FALSE | L24: Already Ordered From the Webstore
A25: 191747 | B25: Alpla | C25: 2976.89 | D25: 46065 | E25: Eric Simpson | F25: 46078 | G25: David McCollum | I25: 2976.89 | J25: Won | K25: FALSE | L25: Ordered on SO# 428153
A26: 191892 | B26: Alpla | C26: 2675.38 | D26: 46066 | E26: Eric Simpson | F26: 46078 | G26: David McCollum | I26: 2675.38 | J26: Won | K26: FALSE | L26: Ordered on SO# 428361
A27: 191457 | B27: Amcor Rigid Plastics | C27: 5422.38 | D27: 46055 | E27: Eric Simpson | F27: 46078 | G27: Clay Craig | I27: 5422.38 | J27: Won | K27: FALSE | L27: Ordered on SO# 427649
A28: 191877 | B28: Aspire Bakeries | C28: 1788 | D28: 46066 | E28: Eric Simpson | F28: 46078 | G28: Gary Marchetti | I28: 1788 | J28: won | K28: FALSE | L28: Ordered on SO# 428222
A29: 191880 | B29: Burlington Coat Factory | C29: 3862.94 | D29: 46066 | E29: Eric Simpson | F29: 46078 | G29: Jasminne Sanchez | K29: FALSE | L29: Sent a second request
A30: 191881 | B30: Burlington Coat Factory | C30: 2365.5 | D30: 46066 | E30: Eric Simpson | F30: 46078 | G30: Jasminne Sanchez | K30: FALSE | L30: Sent a second request
A31: 191459 | B31: Church & Dwight | C31: 6508.2 | D31: 46055 | E31: Eric Simpson | F31: 46078 | G31: Justin Lang | I31: 6508.2 | J31: Won | K31: FALSE | L31: Ordered on SO# 427619
A32: 191828 | B32: Country Pure Foods/Silver Springs Citrus | C32: 2667.14 | D32: 46066 | E32: Eric Simpson | F32: 46078 | G32: Kyle Valentin | I32: 2667.14 | J32: Won | K32: FALSE | L32: Ordered on SO# 428234
A33: 191751 | B33: Furmano Foods | C33: 4299.68 | D33: 46065 | E33: Eric Simpson | F33: 46078 | G33: Scott Fox | I33: 4299.68 | J33: Won | K33: TRUE | L33: Ordered on SO# 428154
A34: 191817 | B34: Gallo Glass / E&J Gallo Winery / G3 Enterprises | C34: 17508.44 | D34: 46064 | E34: Eric Simpson | F34: 46078 | G34: MARTY SHEEK | J34: Lost | K34: FALSE | L34: Ordered cancelled
A35: 191785 | B35: Henkel | C35: 1512 | D35: 46065 | E35: Eric Simpson | F35: 46078 | G35: Amanda Glover | I35: 1512 | J35: Won | K35: FALSE | L35: Ordered on SO# 428178
A36: 191840 | B36: Ken's Foods, LLC | C36: 4912.84 | D36: 46065 | E36: Eric Simpson | F36: 46078 | I36: 4912.84 | J36: Won | K36: FALSE | L36: Ordered on SO# 428179
A37: 191789 | B37: Ocean Spray Cranberries | C37: 2256 | D37: 46066 | E37: Eric Simpson | F37: 46078 | G37: Jeff Bortz | I37: 2256 | J37: Won | K37: FALSE | L37: Ordered on SO# 428274
A38: 191733 | B38: Ryder Integrated Logistics / former Tech Packaging | C38: 1847 | E38: Eric Simpson | F38: 46078 | J38: Lost | K38: FALSE | L38: Order Cancelled
A39: 191777 | B39: S.C. Johnson & Son | C39: 4553.38 | D39: 46065 | E39: Eric Simpson | F39: 46078 | G39: Renee Frederick | I39: 4553.38 | J39: Won | K39: FALSE | L39: Ordered on SO# 428208
A40: 191774 | B40: S.C. Johnson & Son | C40: 1826.25 | D40: 46065 | E40: Eric Simpson | F40: 46078 | G40: Renee Frederick | I40: 1826.25 | J40: Won | K40: FALSE | L40: Ordered on SO# 428213
...

Sheet LuWanna Morris
A1: Quote Number | B1: Cust. Name | C1: Quote Amount | D1: Quote Entry Date | E1: Assignee | F1: Follow Up Date | G1: Contact Name | H1: Contact Number | I1: Actual Order $ | J1: Won/Lost | K1: Won by Follow Up? | L1: Notes | M1: Previous Follow Up Date
A2: 190638 | B2: Sustainable Beef LLC | C2: 3322.91 | D2: 46032 | E2: LuWanna Morris | G2: Mick Henry | J2: lost | K2: FALSE | L2: sent reminder/ close no response | M2: 46051
A3: 191493 | B3: Central Valley Meat Co./ Harris Ranch Beef Co. | C3: 2173 | D3: 46056 | E3: LuWanna Morris | J3: lost | K3: FALSE | L3: close no response
A4: 191497 | B4: Kenosha Beef | C4: 2080 | D4: 46056 | E4: LuWanna Morris | J4: lost | K4: FALSE | L4: close no response
A5: 191493 | B5: Central Valley Meat Co./ Harris Ranch Beef Co. | C5: 2173 | D5: 46056 | E5: LuWanna Morris | J5: lost | K5: FALSE
A6: 191497 | B6: Kenosha Beef | C6: 2080 | D6: 46056 | E6: LuWanna Morris | J6: lost | K6: FALSE
A7: 190511 | B7: Ardagh Group | C7: 4159.33 | D7: 46036 | E7: LuWanna Morris | G7: Brandon Sewell | I7: 1927.79 | J7: won | K7: TRUE | L7: sent reminder/ 428308 | M7: 46051
A8: 191745 | B8: AB Foods aka Washington Beef/True West | C8: 2118 | D8: 46063 | E8: LuWanna Morris | K8: FALSE
A9: 191597 | B9: Alphasite Inc. | C9: 2226.96 | D9: 46059 | E9: LuWanna Morris | K9: FALSE
A10: 191807 | B10: Archer Daniels Mid/Stratas Foods/Wild Flavors | C10: 2238.64 | D10: 46064 | E10: LuWanna Morris | K10: FALSE
A11: 191958 | B11: Arkansas Glass Container | C11: 4890.02 | D11: 46067 | E11: LuWanna Morris | K11: FALSE
A12: 191516 | B12: Baldwin Richardson Foods | C12: 7331.76 | D12: 46057 | E12: LuWanna Morris | K12: FALSE
A13: 191911 | B13: Basic American Foods | C13: 2125.25 | E13: LuWanna Morris | K13: FALSE
A14: 191931 | B14: Church & Dwight | C14: 1926.02 | D14: 46067 | E14: LuWanna Morris | K14: FALSE
A15: 191920 | B15: Coca Cola | C15: 102426.5 | D15: 46066 | E15: LuWanna Morris | K15: FALSE
A16: 191680 | B16: Coca Cola | C16: 21685.14 | D16: 46060 | E16: LuWanna Morris | K16: FALSE
A17: 191679 | B17: Coca Cola | C17: 8042 | E17: LuWanna Morris | K17: FALSE
A18: 191851 | B18: Full Sail Brewing | C18: 4408.86 | D18: 46065 | E18: LuWanna Morris | K18: FALSE
A19: 191699 | B19: General Mills, Inc. | C19: 5362.35 | D19: 46060 | E19: LuWanna Morris | K19: FALSE
A20: 191951 | B20: General Mills, Inc. | C20: 3707.32 | D20: 46067 | E20: LuWanna Morris | K20: FALSE
A21: 191538 | B21: Hamrick Manufacturing | C21: 14038.06 | D21: 46057 | E21: LuWanna Morris | K21: FALSE | L21: RSP
A22: 191752 | B22: JBS USA | C22: 3929.34 | D22: 46063 | E22: LuWanna Morris | K22: FALSE
A23: 191595 | B23: JBS USA | C23: 1586.13 | D23: 46058 | E23: LuWanna Morris | K23: FALSE
A24: 191855 | B24: Kraft Heinz Company | C24: 12004.5 | D24: 46065 | E24: LuWanna Morris | K24: FALSE
A25: 191656 | B25: Lagunitas Brewing Co | C25: 1737 | D25: 46059 | E25: LuWanna Morris | K25: FALSE
A26: 191860 | B26: Leprino Foods Company | C26: 2695 | D26: 46065 | E26: LuWanna Morris | K26: FALSE
A27: 191600 | B27: Midland Paper Co. | C27: 11815.47 | D27: 46065 | E27: LuWanna Morris | K27: FALSE
A28: 191604 | B28: National Beef / Iowa Premium | C28: 6605.8 | D28: 46058 | E28: LuWanna Morris | K28: FALSE
A29: 191847 | B29: Neil Jones Food Company dba Toma Tek | C29: 73111.8 | D29: 46065 | E29: LuWanna Morris | K29: FALSE
A30: 191631 | B30: Niagara Bottling LLC | C30: 2048 | D30: 46059 | E30: LuWanna Morris | K30: FALSE
A31: 191484 | B31: PepsiCo | C31: 28215.55 | E31: LuWanna Morris | K31: FALSE | L31: waiting for procurement
A32: 191786 | B32: Perdue Farms | C32: 9627.14 | D32: 46064 | E32: LuWanna Morris | K32: FALSE | L32: RSP
A33: 191580 | B33: SoJo Industries | C33: 22190.02 | D33: 46059 | E33: LuWanna Morris | K33: FALSE | L33: RSP
A34: 191811 | B34: Sonoco Products Co | C34: 2666 | D34: 46064 | E34: LuWanna Morris | K34: FALSE
A35: 191925 | B35: Ste. Michelle Wine Estates / Columbia Crest Winery | C35: 2488 | D35: 46066 | E35: LuWanna Morris | K35: FALSE
A36: 191674 | B36: Tailored Chemical Products | C36: 21976.59 | D36: 46060 | E36: LuWanna Morris | K36: FALSE | L36: RSP
A37: 191629 | B37: Vallen/Hagemeyer | C37: 2734.91 | D37: 46059 | E37: LuWanna Morris | K37: FALSE
A38: 191946 | B38: Vallen/Hagemeyer | C38: 1757.46 | D38: 46067 | E38: LuWanna Morris | K38: FALSE
A39: 191745 | B39: AB Foods aka Washington Beef/True West | C39: 2118 | D39: 46063 | E39: LuWanna Morris | K39: FALSE
A40: 191807 | B40: Archer Daniels Mid/Stratas Foods/Wild Flavors | C40: 2238.64 | D40: 46064 | E40: LuWanna Morris | K40: FALSE
...

Sheet Reid Kincaid
A1: Quote Number | B1: Cust. Name | C1: Quote Amount | D1: Quote Entry Date | E1: Assignee | F1: Follow Up Date | G1: Contact Name | H1: Contact Number | I1: Actual Order $ | J1: Won/Lost | K1: Won by Follow Up? | L1: Notes | M1: Previous Follow Up Date
A2: 191846 | B2: Church & Dwight | C2: 2119.5 | D2: 46065 | E2: Reid Kincaid | J2: Won | K2: FALSE
A3: 191927 | B3: Kari-Out Company | C3: 1950.28 | D3: 46066 | E3: Reid Kincaid | F3: 46080 | G3: Gabriela Quinde <gquinde@kariout.com> | K3: FALSE
A4: 191471 | B4: Logoplaste USA | C4: 3461.38 | D4: 46056 | E4: Reid Kincaid | J4: Won | K4: FALSE
A5: 191710 | B5: Niagara Bottling LLC | C5: 4421 | D5: 46062 | E5: Reid Kincaid | J5: Won | K5: FALSE
A6: 191711 | B6: Perdue Farms | C6: 2007.6 | D6: 46062 | E6: Reid Kincaid | F6: 46080 | G6: levary.little@perdue.com | K6: FALSE
A7: 191502 | B7: Tyson Foods, Inc. HQ | C7: 3492.86 | D7: 46056 | E7: Reid Kincaid | J7: Won | K7: FALSE
B9: Total | C9: =SUM(Reid[Quote Amount]) -> 17452.62

Sheet Summary
A1: Primary Sales Rep | B1: Quotes (#) | C1: Customers (#) | D1: Total Potential $ | E1: Avg $/Quote | F1: Amount Recoverd $ | G1: Amount by Follow Up Only | H1: Contacts Made
A2: LuWanna Morris | B2: =COUNTA(LuWanna[Quote Number]) -> 67 | C2: =COUNTA(_xlfn.UNIQUE(LuWanna[Cust. Name])) -> 33 | D2: ='LuWanna Morris'!C72 -> 791192.27 | E2: =AVERAGE(LuWanna[Quote Amount]) -> 11890.868 | F2: =SUMIF(LuWanna[Won/Lost], "Won", LuWanna[Actual Order $]) -> 1927.79 | G2: =SUMIFS(LuWanna[Actual Order $], LuWanna[Won/Lost],"Won", LuWanna[Won by Follow Up?], TRUE) -> 1927.79 | H2: =COUNTA(LuWanna[Follow Up Date]) -> 0
A3: Brent Schrader | B3: =COUNTA(Brent[Quote Number]) -> 77 | C3: =COUNTA(_xlfn.UNIQUE(Brent[Cust. Name])) -> 34 | D3: ='Brent Schrader'!C82 -> 699231.64 | E3: =AVERAGE(Brent[Quote Amount]) -> 9080.9304 | F3: =SUMIF(Brent[Won/Lost], "Won", Brent[Actual Order $]) -> 124481 | G3: =SUMIFS(Brent[Actual Order $], Brent[Won/Lost],"Won", Brent[Won by Follow Up?], TRUE) -> 27024 | H3: =COUNTA(Brent[Follow Up Date]) -> 77
A4: Reid Kincaid | B4: =COUNTA(Reid[Quote Number]) -> 6 | C4: =COUNTA(_xlfn.UNIQUE('Reid Kincaid'!B2:B7)) -> 6 | D4: ='Reid Kincaid'!C9 -> 17452.62 | E4: =AVERAGE(Reid[Quote Amount]) -> 2908.77 | F4: =SUMIF(Reid[Won/Lost], "Won", Reid[Actual Order $]) -> 0 | G4: =SUMIFS(Reid[Actual Order $], Reid[Won/Lost],"Won", Reid[Won by Follow Up?], TRUE) -> 0 | H4: =COUNTA(Reid[Follow Up Date]) -> 2
A5: Eric Simpson | B5: =COUNTA(Eric[Quote Number]) -> 47 | C5: =COUNTA(_xlfn.UNIQUE(Eric[Cust. Name])) -> 22 | D5: ='Eric Simpson'!C51 -> 245899.48 | E5: =AVERAGE(Eric[Quote Amount]) -> 5231.9038 | F5: =SUMIF(Eric[Won/Lost], "Won", Eric[Actual Order $]) -> 123358.93 | G5: =SUMIFS(Eric[Actual Order $], Eric[Won/Lost],"Won", Eric[Won by Follow Up?], TRUE) -> 9533.02 | H5: =COUNTA(Eric[Follow Up Date]) -> 47
A6: Tami Knoell | B6: =COUNTA(Tami[Quote Number]) -> 16 | C6: =COUNTA(_xlfn.UNIQUE(Tami[Cust. Name])) -> 16 | D6: ='Tami Knoell'!C21 -> 61102.2 | E6: =AVERAGE(Tami[Quote Amount]) -> 3818.8875 | F6: =SUMIF(Tami[Won/Lost], "Won", Tami[Actual Order $]) -> 31295.31 | G6: =SUMIFS(Tami[Actual Order $], Tami[Won/Lost],"Won", Tami[Won by Follow Up?], TRUE) -> 0 | H6: =COUNTA(Tami[Follow Up Date]) -> 16
A7: Totals | B7: =SUBTOTAL(109,B2:B6) -> 213 | C7: =SUBTOTAL(109,C2:C6) -> 111 | D7: =SUBTOTAL(109,D2:D6) -> 1814878.2 | E7: =AVERAGE(E2:E6) -> 6586.272 | F7: =SUM(F2:F6) -> 281063.03 | G7: =SUM(G2:G6) -> 38484.81 | H7: =SUM(H2:H6) -> 142
B10: Total Quotes Won | C10: =COUNTIF('Master Allocation'!J2:J77, "Won") -> 36
B11: % Quotes Won | C11: =_xlfn.PERCENTOF(C10,B7) -> 0.16901408
B12: Total Revenue Confirmed | C12: =F7 -> 281063.03
B13: Total Converted w/ FU | C13: =COUNTIFS('Master Allocation'!J:J, "Won", 'Master Allocation'!K:K, "TRUE") -> 8
B14: % Quotes Won w/ FU | C14: =_xlfn.PERCENTOF(C13,B7) -> 0.037558685
B15: Total by Follow Up Only | C15: =G7 -> 38484.81 | D15: =_xlfn.PERCENTOF(C15,D7) -> 0.021205175
